<?xml version="1.0" ?>


<!-- -0.09019  0.21836 -0.01529 -->
<robot name="myrobot" xmlns:xacro="http://www.ros.org/wiki/xacro">

  <xacro:include filename="$(find mybot_description)/urdf/mybot.gazebo" />
  <xacro:include filename="$(find mybot_description)/urdf/materials.xacro" />
  <xacro:include filename="$(find mybot_description)/urdf/macros.xacro" />

  <joint name="left_wheel_hinge" type="continuous">
    <parent link="chassis"/>
    <child link="left_wheel"/>
    <origin rpy="0  0  0" xyz="-0.09019  0.21836 -0.01529"/>
    <axis xyz="0 1 0"/>
    <limit effort="100" velocity="100"/>
  </joint>

  <joint name="right_wheel_hinge" type="continuous">
    <parent link="chassis"/>
    <child link="right_wheel"/>
    <origin rpy="0  0  0" xyz="-0.09019 -0.19163 -0.01529"/>
    <axis xyz="0 1 0"/>
    <limit effort="100"  velocity="100"/>
  </joint>
  

  <link name="chassis">
    <inertial>
      <mass value="10"/>
        <origin rpy="0  0  0" xyz="0.0748 0.01336 -0.01529"/>
      <inertia ixx="0.5" ixy="0" ixz="0" 
               iyy="1.0" iyz="0" 
               izz="0.1"/>
    </inertial>
    <collision name="collision">
      <origin rpy="0  0  0" xyz="0.0748 0.01336 -0.01529"/>
      <geometry>
        <box size="0.54 0.49 0.03"/>
      </geometry>
    </collision>
    <visual name="chassis_visual">
<!--  <geometry>
        <box size="0.54 0.34 0.03"/>
      </geometry>
-->
      <origin rpy="0  0  0" xyz="0.0748 0.01336 -0.01529"/>
      <geometry>
        <box size="0.54 0.49 0.03"/>
      </geometry>
    </visual>

    <collision name="support">
      <origin rpy="0  0  0" xyz="0.03 0 0.075"/>
      <geometry>
        <box size="0.05 0.05 0.15"/>
      </geometry>
    </collision>
    <visual name="support_visual">
      <origin rpy="0  0  0" xyz="0.03 0 0.075"/>
      <geometry>
        <box size="0.1 0.1 0.15"/>
      </geometry>
    </visual>

    <collision name='caster_collision'>
      <origin xyz="0.264801 0.013363 -0.06" rpy=" 0 0 0"/>
      <geometry>
        <sphere radius="0.06"/>
      </geometry>
      <surface>
        <friction>
          <ode>
            <mu>0</mu>
            <mu2>0</mu2>
            <slip1>1.0</slip1>
            <slip2>1.0</slip2>
          </ode>
        </friction>
      </surface>
    </collision>

    <visual name='caster_visual'>
      <origin xyz="0.264801 0.013363 -0.06" rpy=" 0 0 0"/>
      <geometry>
        <sphere radius="0.06"/>
      </geometry>
    </visual>
  </link>

  <link name="right_wheel">
    <collision name="collision">
      <origin rpy="0  1.5707 1.5707" xyz="0 0 0"/>
      <geometry>
        <cylinder length="0.05" radius="0.1"/>
      </geometry>
    </collision>
    <visual name="right_wheel_visual">
      <origin rpy="0  1.5707 1.5707" xyz="0 0 0"/>
      <geometry>
        <cylinder length="0.05" radius="0.1"/>
      </geometry>
    </visual>
    <inertial>
      <mass value="5"/>
      <origin rpy="0  1.5707 1.5707" xyz="0 0 0"/>
      <inertia
        ixx="1.0" ixy="0.0" ixz="0.0"
        iyy="1.0" iyz="0.0"
        izz="1.0"/>
    </inertial>
  </link>

  <link name="left_wheel">
    <collision name="collision">
      <origin rpy="0 1.5707 1.5707" xyz="0 0 0"/>
      <geometry>
        <cylinder length="0.05" radius="0.1"/>
      </geometry>
    </collision>
    <visual name="left_wheel_visual">
      <origin rpy="0 1.5707 1.5707" xyz="0 0 0"/>
      <geometry>
        <cylinder length="0.05" radius="0.1"/>
      </geometry>
    </visual>
    <inertial>
      <mass value="5"/>
      <origin rpy="0 1.5707 1.5707" xyz="0 0 0"/>
      <inertia
        ixx="1.0" ixy="0.0" ixz="0.0"
        iyy="1.0" iyz="0.0"
        izz="1.0"/>
    </inertial>
  </link>

    <joint name="laser_base_joint" type="fixed">
      <parent link="chassis"/>
      <origin xyz="0.035 0 0.15" rpy="0 0 0"/>
      <child link="laser_base_link"/>
    </joint>
  
    
    <link name="laser_base_link">
      <collision>
        <origin xyz="0 0 0" rpy="0 0 0"/>
        <geometry>
         <mesh filename="package://mybot_description/meshes/rplidar_a2.dae"/>
        </geometry>
      </collision>
  
      <visual>
        <origin xyz="0 0 0" rpy="0 0 0"/>
        <geometry>
            <mesh filename="package://mybot_description/meshes/rplidar_a2.dae"/>
        </geometry>
      </visual>

      <inertial>
        <mass value="1e-5" />
        <origin xyz="0 0 0" rpy="0 0 0"/>
        <inertia ixx="1e-6" ixy="0" ixz="0" iyy="1e-6" iyz="0" izz="1e-6" />
      </inertial>
    </link>
    
    <joint name="laser_laser_joint" type="fixed">
      <origin xyz="0 0 0.03086" rpy="0 0 3.1415"/>
      <parent link="laser_base_link"/>
      <child link="laser"/>
    </joint>
  
    
    <link name="laser">
    </link>
    


</robot>
